Workbook

Sheet Cleaned_sheet
A1: Transaction ID | B1: Date | C1: Type | D1: Category | E1: Department | F1: Description | G1: Amount (USD) | H1: Currency | I1: Rep / Vendor | J1: Month | K1: Quarter | L1: Notes | N1: Department_Clean | O1: Date_Clean | P1: Raw Variant | Q1: Clean Name | R1: Month_Clean | S1: Quarter_Clean | T1: Amount_Clean_USD
A2: TXN-1003 | B2: 09-01-2024 | C2: Revenue | D2: Subscription | E2: Sales Dept | F2: Subscription - Pinnacle Systems | G2: 68037.03 | H2: USD | I2: James Okafor | J2: Jan | K2: Q1 | N2: =IFERROR(VLOOKUP(TRIM(E2),$P$2:$Q$23,2,FALSE),"UNMAPPED - CHECK") -> Sales | O2: =IFERROR(__xludf.DUMMYFUNCTION("IFERROR( IF(LEN(TRIM(B2))=6, DATE(2000+VALUE(RIGHT(TRIM(B2),2)),MATCH(LEFT(TRIM(B2),3),{""Jan"",""Feb"",""Mar"",""Apr"",""May"",""Jun"",""Jul"",""Aug"",""Sep"",""Oct"",""Nov"",""Dec""},0),15), IF(REGEXMATCH(TRIM(B2),""^\d{2}[/-]\d{2}[/-]\d{4}$""),"&" DATE(VALUE(RIGHT(TRIM(B2),4)),VALUE(MID(TRIM(B2),4,2)),VALUE(LEFT(TRIM(B2),2))), DATEVALUE(TRIM(B2)))), ""CHECK"")"),45300.0) -> 45300 | P2: CLOUD | Q2: Cloud Infrastructure | R2: =IF(O2="CHECK","CHECK",TEXT(O2,"mmm")) -> Jan | S2: =IF(O2="CHECK","CHECK","Q"&INT((MONTH(O2)-1)/3)+1) -> Q1 | T2: =IFERROR(IF(G2="see notes",IF(ISNUMBER(VALUE(L2)),VALUE(L2),0),IF(G2="",0,IF(H2="GBP",VALUE(G2)*1.27,IF(AND(ISNUMBER(VALUE(G2)),F2="Revenue",VALUE(G2)<0),ABS(VALUE(G2)),IF(ISNUMBER(VALUE(G2)),VALUE(G2),0))))),0) -> 68037.03
A3: TXN-1519 | B3: 2024-12-25 | C3: Expense | D3: Cloud Infrastructure | E3: cloud infra | F3: Contractor - Delta Airlines | G3: 39375.28 | H3: USD | I3: Delta Airlines | J3: Dec | K3: Q4 | N3: =IFERROR(VLOOKUP(TRIM(E3),$P$2:$Q$23,2,FALSE),"UNMAPPED - CHECK") -> Cloud Infrastructure | O3: =IFERROR(__xludf.DUMMYFUNCTION("IFERROR( IF(LEN(TRIM(B3))=6, DATE(2000+VALUE(RIGHT(TRIM(B3),2)),MATCH(LEFT(TRIM(B3),3),{""Jan"",""Feb"",""Mar"",""Apr"",""May"",""Jun"",""Jul"",""Aug"",""Sep"",""Oct"",""Nov"",""Dec""},0),15), IF(REGEXMATCH(TRIM(B3),""^\d{2}[/-]\d{2}[/-]\d{4}$""),"&" DATE(VALUE(RIGHT(TRIM(B3),4)),VALUE(MID(TRIM(B3),4,2)),VALUE(LEFT(TRIM(B3),2))), DATEVALUE(TRIM(B3)))), ""CHECK"")"),45651.0) -> 45651 | P3: Cloud Infrastructure | Q3: Cloud Infrastructure | R3: =IF(O3="CHECK","CHECK",TEXT(O3,"mmm")) -> Dec | S3: =IF(O3="CHECK","CHECK","Q"&INT((MONTH(O3)-1)/3)+1) -> Q4 | T3: =IFERROR(IF(G3="see notes",IF(ISNUMBER(VALUE(L3)),VALUE(L3),0),IF(G3="",0,IF(H3="GBP",VALUE(G3)*1.27,IF(AND(ISNUMBER(VALUE(G3)),F3="Revenue",VALUE(G3)<0),ABS(VALUE(G3)),IF(ISNUMBER(VALUE(G3)),VALUE(G3),0))))),0) -> 39375.28
A4: TXN-1083 | B4: 03/20/2024 | C4: Revenue | D4: Subscription | E4: Sales Dept | F4: Subscription - Redwood Partners | G4: 251866.75 | H4: USD | I4: Aisha Rahman | J4: Mar | K4: Q1 | N4: =IFERROR(VLOOKUP(TRIM(E4),$P$2:$Q$23,2,FALSE),"UNMAPPED - CHECK") -> Sales | O4: =IFERROR(__xludf.DUMMYFUNCTION("IFERROR( IF(LEN(TRIM(B4))=6, DATE(2000+VALUE(RIGHT(TRIM(B4),2)),MATCH(LEFT(TRIM(B4),3),{""Jan"",""Feb"",""Mar"",""Apr"",""May"",""Jun"",""Jul"",""Aug"",""Sep"",""Oct"",""Nov"",""Dec""},0),15), IF(REGEXMATCH(TRIM(B4),""^\d{2}[/-]\d{2}[/-]\d{4}$""),"&" DATE(VALUE(RIGHT(TRIM(B4),4)),VALUE(MID(TRIM(B4),4,2)),VALUE(LEFT(TRIM(B4),2))), DATEVALUE(TRIM(B4)))), ""CHECK"")"),45872.0) -> 45872 | P4: cloud infra | Q4: Cloud Infrastructure | R4: =IF(O4="CHECK","CHECK",TEXT(O4,"mmm")) -> Aug | S4: =IF(O4="CHECK","CHECK","Q"&INT((MONTH(O4)-1)/3)+1) -> Q3 | T4: =IFERROR(IF(G4="see notes",IF(ISNUMBER(VALUE(L4)),VALUE(L4),0),IF(G4="",0,IF(H4="GBP",VALUE(G4)*1.27,IF(AND(ISNUMBER(VALUE(G4)),F4="Revenue",VALUE(G4)<0),ABS(VALUE(G4)),IF(ISNUMBER(VALUE(G4)),VALUE(G4),0))))),0) -> 251866.75
A5: TXN-1428 | B5: October 22, 2024 | C5: Expense | D5: Cloud Infrastructure | E5: CLOUD | F5: Salary - Accenture | G5: 22219.83 | H5: USD | I5: Accenture | J5: Oct | K5: Q4 | N5: =IFERROR(VLOOKUP(TRIM(E5),$P$2:$Q$23,2,FALSE),"UNMAPPED - CHECK") -> Cloud Infrastructure | O5: =IFERROR(__xludf.DUMMYFUNCTION("IFERROR( IF(LEN(TRIM(B5))=6, DATE(2000+VALUE(RIGHT(TRIM(B5),2)),MATCH(LEFT(TRIM(B5),3),{""Jan"",""Feb"",""Mar"",""Apr"",""May"",""Jun"",""Jul"",""Aug"",""Sep"",""Oct"",""Nov"",""Dec""},0),15), IF(REGEXMATCH(TRIM(B5),""^\d{2}[/-]\d{2}[/-]\d{4}$""),"&" DATE(VALUE(RIGHT(TRIM(B5),4)),VALUE(MID(TRIM(B5),4,2)),VALUE(LEFT(TRIM(B5),2))), DATEVALUE(TRIM(B5)))), ""CHECK"")"),45587.0) -> 45587 | P5: CS | Q5: Customer Success | R5: =IF(O5="CHECK","CHECK",TEXT(O5,"mmm")) -> Oct | S5: =IF(O5="CHECK","CHECK","Q"&INT((MONTH(O5)-1)/3)+1) -> Q4 | T5: =IFERROR(IF(G5="see notes",IF(ISNUMBER(VALUE(L5)),VALUE(L5),0),IF(G5="",0,IF(H5="GBP",VALUE(G5)*1.27,IF(AND(ISNUMBER(VALUE(G5)),F5="Revenue",VALUE(G5)<0),ABS(VALUE(G5)),IF(ISNUMBER(VALUE(G5)),VALUE(G5),0))))),0) -> 22219.83
A6: TXN-1276 | B6: 03-07-2024 | C6: Expense | D6: Marketing | E6: marketing | F6: Salary - Hilton Hotels | G6: 54150.77 | H6: USD | I6: Hilton Hotels | J6: Jul | K6: Q3 | N6: =IFERROR(VLOOKUP(TRIM(E6),$P$2:$Q$23,2,FALSE),"UNMAPPED - CHECK") -> Marketing | O6: =IFERROR(__xludf.DUMMYFUNCTION("IFERROR( IF(LEN(TRIM(B6))=6, DATE(2000+VALUE(RIGHT(TRIM(B6),2)),MATCH(LEFT(TRIM(B6),3),{""Jan"",""Feb"",""Mar"",""Apr"",""May"",""Jun"",""Jul"",""Aug"",""Sep"",""Oct"",""Nov"",""Dec""},0),15), IF(REGEXMATCH(TRIM(B6),""^\d{2}[/-]\d{2}[/-]\d{4}$""),"&" DATE(VALUE(RIGHT(TRIM(B6),4)),VALUE(MID(TRIM(B6),4,2)),VALUE(LEFT(TRIM(B6),2))), DATEVALUE(TRIM(B6)))), ""CHECK"")"),45476.0) -> 45476 | P6: Customer Success | Q6: Customer Success | R6: =IF(O6="CHECK","CHECK",TEXT(O6,"mmm")) -> Jul | S6: =IF(O6="CHECK","CHECK","Q"&INT((MONTH(O6)-1)/3)+1) -> Q3 | T6: =IFERROR(IF(G6="see notes",IF(ISNUMBER(VALUE(L6)),VALUE(L6),0),IF(G6="",0,IF(H6="GBP",VALUE(G6)*1.27,IF(AND(ISNUMBER(VALUE(G6)),F6="Revenue",VALUE(G6)<0),ABS(VALUE(G6)),IF(ISNUMBER(VALUE(G6)),VALUE(G6),0))))),0) -> 54150.77
A7: TXN-1129 | B7: April 14, 2024 | C7: Revenue | D7: Licensing | E7: sales | F7: Licensing - Redwood Partners | G7: 6708.47 | H7: USD | I7: Priya Nair | J7: Apr | K7: Q2 | N7: =IFERROR(VLOOKUP(TRIM(E7),$P$2:$Q$23,2,FALSE),"UNMAPPED - CHECK") -> Sales | O7: =IFERROR(__xludf.DUMMYFUNCTION("IFERROR( IF(LEN(TRIM(B7))=6, DATE(2000+VALUE(RIGHT(TRIM(B7),2)),MATCH(LEFT(TRIM(B7),3),{""Jan"",""Feb"",""Mar"",""Apr"",""May"",""Jun"",""Jul"",""Aug"",""Sep"",""Oct"",""Nov"",""Dec""},0),15), IF(REGEXMATCH(TRIM(B7),""^\d{2}[/-]\d{2}[/-]\d{4}$""),"&" DATE(VALUE(RIGHT(TRIM(B7),4)),VALUE(MID(TRIM(B7),4,2)),VALUE(LEFT(TRIM(B7),2))), DATEVALUE(TRIM(B7)))), ""CHECK"")"),45396.0) -> 45396 | P7: Customer Suc. | Q7: Customer Success | R7: =IF(O7="CHECK","CHECK",TEXT(O7,"mmm")) -> Apr | S7: =IF(O7="CHECK","CHECK","Q"&INT((MONTH(O7)-1)/3)+1) -> Q2 | T7: =IFERROR(IF(G7="see notes",IF(ISNUMBER(VALUE(L7)),VALUE(L7),0),IF(G7="",0,IF(H7="GBP",VALUE(G7)*1.27,IF(AND(ISNUMBER(VALUE(G7)),F7="Revenue",VALUE(G7)<0),ABS(VALUE(G7)),IF(ISNUMBER(VALUE(G7)),VALUE(G7),0))))),0) -> 6708.47
A8: TXN-1348 | B8: 2024-09-15 | C8: Revenue | D8: Subscription | E8: sales | F8: Subscription - Apex Retail | G8: 149903.37 | H8: USD | I8: Kwame Asante | J8: Sep | K8: Q3 | N8: =IFERROR(VLOOKUP(TRIM(E8),$P$2:$Q$23,2,FALSE),"UNMAPPED - CHECK") -> Sales | O8: =IFERROR(__xludf.DUMMYFUNCTION("IFERROR( IF(LEN(TRIM(B8))=6, DATE(2000+VALUE(RIGHT(TRIM(B8),2)),MATCH(LEFT(TRIM(B8),3),{""Jan"",""Feb"",""Mar"",""Apr"",""May"",""Jun"",""Jul"",""Aug"",""Sep"",""Oct"",""Nov"",""Dec""},0),15), IF(REGEXMATCH(TRIM(B8),""^\d{2}[/-]\d{2}[/-]\d{4}$""),"&" DATE(VALUE(RIGHT(TRIM(B8),4)),VALUE(MID(TRIM(B8),4,2)),VALUE(LEFT(TRIM(B8),2))), DATEVALUE(TRIM(B8)))), ""CHECK"")"),45550.0) -> 45550 | P8: Cust Success | Q8: Customer Success | R8: =IF(O8="CHECK","CHECK",TEXT(O8,"mmm")) -> Sep | S8: =IF(O8="CHECK","CHECK","Q"&INT((MONTH(O8)-1)/3)+1) -> Q3 | T8: =IFERROR(IF(G8="see notes",IF(ISNUMBER(VALUE(L8)),VALUE(L8),0),IF(G8="",0,IF(H8="GBP",VALUE(G8)*1.27,IF(AND(ISNUMBER(VALUE(G8)),F8="Revenue",VALUE(G8)<0),ABS(VALUE(G8)),IF(ISNUMBER(VALUE(G8)),VALUE(G8),0))))),0) -> 149903.37
A9: TXN-1295 | B9: 07/21/2024 | C9: Expense | D9: Cloud Infrastructure | E9: Cloud | F9: Legal - Salesforce | G9: 10013.89 | H9: GBP | I9: Salesforce | J9: Jul | K9: Q3 | N9: =IFERROR(VLOOKUP(TRIM(E9),$P$2:$Q$23,2,FALSE),"UNMAPPED - CHECK") -> Cloud Infrastructure | O9: =IFERROR(__xludf.DUMMYFUNCTION("IFERROR( IF(LEN(TRIM(B9))=6, DATE(2000+VALUE(RIGHT(TRIM(B9),2)),MATCH(LEFT(TRIM(B9),3),{""Jan"",""Feb"",""Mar"",""Apr"",""May"",""Jun"",""Jul"",""Aug"",""Sep"",""Oct"",""Nov"",""Dec""},0),15), IF(REGEXMATCH(TRIM(B9),""^\d{2}[/-]\d{2}[/-]\d{4}$""),"&" DATE(VALUE(RIGHT(TRIM(B9),4)),VALUE(MID(TRIM(B9),4,2)),VALUE(LEFT(TRIM(B9),2))), DATEVALUE(TRIM(B9)))), ""CHECK"")"),45907.0) -> 45907 | P9: Eng | Q9: Engineering | R9: =IF(O9="CHECK","CHECK",TEXT(O9,"mmm")) -> Sep | S9: =IF(O9="CHECK","CHECK","Q"&INT((MONTH(O9)-1)/3)+1) -> Q3 | T9: =IFERROR(IF(G9="see notes",IF(ISNUMBER(VALUE(L9)),VALUE(L9),0),IF(G9="",0,IF(H9="GBP",VALUE(G9)*1.27,IF(AND(ISNUMBER(VALUE(G9)),F9="Revenue",VALUE(G9)<0),ABS(VALUE(G9)),IF(ISNUMBER(VALUE(G9)),VALUE(G9),0))))),0) -> 12717.64
A10: TXN-1170 | B10: 10-05-2024 | C10: Revenue | D10: Professional Services | E10: Sales Dept | F10: Professional Services - Altura Health | G10: 21411.91 | H10: USD | I10: Kwame Asante | J10: May | K10: Q2 | N10: =IFERROR(VLOOKUP(TRIM(E10),$P$2:$Q$23,2,FALSE),"UNMAPPED - CHECK") -> Sales | O10: =IFERROR(__xludf.DUMMYFUNCTION("IFERROR( IF(LEN(TRIM(B10))=6, DATE(2000+VALUE(RIGHT(TRIM(B10),2)),MATCH(LEFT(TRIM(B10),3),{""Jan"",""Feb"",""Mar"",""Apr"",""May"",""Jun"",""Jul"",""Aug"",""Sep"",""Oct"",""Nov"",""Dec""},0),15), IF(REGEXMATCH(TRIM(B10),""^\d{2}[/-]\d{2}[/-]\d{4}$"&"""), DATE(VALUE(RIGHT(TRIM(B10),4)),VALUE(MID(TRIM(B10),4,2)),VALUE(LEFT(TRIM(B10),2))), DATEVALUE(TRIM(B10)))), ""CHECK"")"),45422.0) -> 45422 | P10: Engineering | Q10: Engineering | R10: =IF(O10="CHECK","CHECK",TEXT(O10,"mmm")) -> May | S10: =IF(O10="CHECK","CHECK","Q"&INT((MONTH(O10)-1)/3)+1) -> Q2 | T10: =IFERROR(IF(G10="see notes",IF(ISNUMBER(VALUE(L10)),VALUE(L10),0),IF(G10="",0,IF(H10="GBP",VALUE(G10)*1.27,IF(AND(ISNUMBER(VALUE(G10)),F10="Revenue",VALUE(G10)<0),ABS(VALUE(G10)),IF(ISNUMBER(VALUE(G10)),VALUE(G10),0))))),0) -> 21411.91
A11: TXN-1379 | B11: Sep-24 | C11: Expense | D11: G&A | E11: G and A | F11: Legal - WeWork | G11: 9918.62 | H11: USD | I11: WeWork | J11: Sep | K11: Q3 | N11: =IFERROR(VLOOKUP(TRIM(E11),$P$2:$Q$23,2,FALSE),"UNMAPPED - CHECK") -> G&A | O11: =IFERROR(__xludf.DUMMYFUNCTION("IFERROR( IF(LEN(TRIM(B11))=6, DATE(2000+VALUE(RIGHT(TRIM(B11),2)),MATCH(LEFT(TRIM(B11),3),{""Jan"",""Feb"",""Mar"",""Apr"",""May"",""Jun"",""Jul"",""Aug"",""Sep"",""Oct"",""Nov"",""Dec""},0),15), IF(REGEXMATCH(TRIM(B11),""^\d{2}[/-]\d{2}[/-]\d{4}$"&"""), DATE(VALUE(RIGHT(TRIM(B11),4)),VALUE(MID(TRIM(B11),4,2)),VALUE(LEFT(TRIM(B11),2))), DATEVALUE(TRIM(B11)))), ""CHECK"")"),45550.0) -> 45550 | P11: R&D | Q11: Engineering | R11: =IF(O11="CHECK","CHECK",TEXT(O11,"mmm")) -> Sep | S11: =IF(O11="CHECK","CHECK","Q"&INT((MONTH(O11)-1)/3)+1) -> Q3 | T11: =IFERROR(IF(G11="see notes",IF(ISNUMBER(VALUE(L11)),VALUE(L11),0),IF(G11="",0,IF(H11="GBP",VALUE(G11)*1.27,IF(AND(ISNUMBER(VALUE(G11)),F11="Revenue",VALUE(G11)<0),ABS(VALUE(G11)),IF(ISNUMBER(VALUE(G11)),VALUE(G11),0))))),0) -> 9918.62
A12: TXN-1131 | B12: 06/04/2024 | C12: Revenue | D12: Licensing | E12: SALES | F12: Licensing - BlueSky Logistics | G12: 6750.78 | H12: USD | I12: Kwame Asante | J12: Apr | K12: Q2 | N12: =IFERROR(VLOOKUP(TRIM(E12),$P$2:$Q$23,2,FALSE),"UNMAPPED - CHECK") -> Sales | O12: =IFERROR(__xludf.DUMMYFUNCTION("IFERROR( IF(LEN(TRIM(B12))=6, DATE(2000+VALUE(RIGHT(TRIM(B12),2)),MATCH(LEFT(TRIM(B12),3),{""Jan"",""Feb"",""Mar"",""Apr"",""May"",""Jun"",""Jul"",""Aug"",""Sep"",""Oct"",""Nov"",""Dec""},0),15), IF(REGEXMATCH(TRIM(B12),""^\d{2}[/-]\d{2}[/-]\d{4}$"&"""), DATE(VALUE(RIGHT(TRIM(B12),4)),VALUE(MID(TRIM(B12),4,2)),VALUE(LEFT(TRIM(B12),2))), DATEVALUE(TRIM(B12)))), ""CHECK"")"),45388.0) -> 45388 | P12: engineering | Q12: Engineering | R12: =IF(O12="CHECK","CHECK",TEXT(O12,"mmm")) -> Apr | S12: =IF(O12="CHECK","CHECK","Q"&INT((MONTH(O12)-1)/3)+1) -> Q2 | T12: =IFERROR(IF(G12="see notes",IF(ISNUMBER(VALUE(L12)),VALUE(L12),0),IF(G12="",0,IF(H12="GBP",VALUE(G12)*1.27,IF(AND(ISNUMBER(VALUE(G12)),F12="Revenue",VALUE(G12)<0),ABS(VALUE(G12)),IF(ISNUMBER(VALUE(G12)),VALUE(G12),0))))),0) -> 6750.78
A13: TXN-1117 | B13: Mar-24 | C13: Expense | D13: Cloud Infrastructure | E13: Cloud | F13: Recruiting - Randstad | G13: 16812.38 | H13: USD | I13: Randstad | J13: Mar | K13: Q1 | N13: =IFERROR(VLOOKUP(TRIM(E13),$P$2:$Q$23,2,FALSE),"UNMAPPED - CHECK") -> Cloud Infrastructure | O13: =IFERROR(__xludf.DUMMYFUNCTION("IFERROR( IF(LEN(TRIM(B13))=6, DATE(2000+VALUE(RIGHT(TRIM(B13),2)),MATCH(LEFT(TRIM(B13),3),{""Jan"",""Feb"",""Mar"",""Apr"",""May"",""Jun"",""Jul"",""Aug"",""Sep"",""Oct"",""Nov"",""Dec""},0),15), IF(REGEXMATCH(TRIM(B13),""^\d{2}[/-]\d{2}[/-]\d{4}$"&"""), DATE(VALUE(RIGHT(TRIM(B13),4)),VALUE(MID(TRIM(B13),4,2)),VALUE(LEFT(TRIM(B13),2))), DATEVALUE(TRIM(B13)))), ""CHECK"")"),45366.0) -> 45366 | P13: G & A | Q13: G&A | R13: =IF(O13="CHECK","CHECK",TEXT(O13,"mmm")) -> Mar | S13: =IF(O13="CHECK","CHECK","Q"&INT((MONTH(O13)-1)/3)+1) -> Q1 | T13: =IFERROR(IF(G13="see notes",IF(ISNUMBER(VALUE(L13)),VALUE(L13),0),IF(G13="",0,IF(H13="GBP",VALUE(G13)*1.27,IF(AND(ISNUMBER(VALUE(G13)),F13="Revenue",VALUE(G13)<0),ABS(VALUE(G13)),IF(ISNUMBER(VALUE(G13)),VALUE(G13),0))))),0) -> 16812.38
A14: TXN-1328 | B14: Aug-24 | C14: Expense | D14: Engineering | E14: Eng | F14: Salary - Delta Airlines | G14: 21612.23 | H14: USD | I14: Delta Airlines | J14: Aug | K14: Q3 | N14: =IFERROR(VLOOKUP(TRIM(E14),$P$2:$Q$23,2,FALSE),"UNMAPPED - CHECK") -> Engineering | O14: =IFERROR(__xludf.DUMMYFUNCTION("IFERROR( IF(LEN(TRIM(B14))=6, DATE(2000+VALUE(RIGHT(TRIM(B14),2)),MATCH(LEFT(TRIM(B14),3),{""Jan"",""Feb"",""Mar"",""Apr"",""May"",""Jun"",""Jul"",""Aug"",""Sep"",""Oct"",""Nov"",""Dec""},0),15), IF(REGEXMATCH(TRIM(B14),""^\d{2}[/-]\d{2}[/-]\d{4}$"&"""), DATE(VALUE(RIGHT(TRIM(B14),4)),VALUE(MID(TRIM(B14),4,2)),VALUE(LEFT(TRIM(B14),2))), DATEVALUE(TRIM(B14)))), ""CHECK"")"),45519.0) -> 45519 | P14: G&A | Q14: G&A | R14: =IF(O14="CHECK","CHECK",TEXT(O14,"mmm")) -> Aug | S14: =IF(O14="CHECK","CHECK","Q"&INT((MONTH(O14)-1)/3)+1) -> Q3 | T14: =IFERROR(IF(G14="see notes",IF(ISNUMBER(VALUE(L14)),VALUE(L14),0),IF(G14="",0,IF(H14="GBP",VALUE(G14)*1.27,IF(AND(ISNUMBER(VALUE(G14)),F14="Revenue",VALUE(G14)<0),ABS(VALUE(G14)),IF(ISNUMBER(VALUE(G14)),VALUE(G14),0))))),0) -> 21612.23
A15: TXN-1225 | B15: 2024-06-28 | C15: Expense | D15: Sales | E15: Sales | F15: Ad Spend - Hilton Hotels | G15: 10129.21 | H15: USD | I15: Hilton Hotels | J15: Jun | K15: Q2 | N15: =IFERROR(VLOOKUP(TRIM(E15),$P$2:$Q$23,2,FALSE),"UNMAPPED - CHECK") -> Sales | O15: =IFERROR(__xludf.DUMMYFUNCTION("IFERROR( IF(LEN(TRIM(B15))=6, DATE(2000+VALUE(RIGHT(TRIM(B15),2)),MATCH(LEFT(TRIM(B15),3),{""Jan"",""Feb"",""Mar"",""Apr"",""May"",""Jun"",""Jul"",""Aug"",""Sep"",""Oct"",""Nov"",""Dec""},0),15), IF(REGEXMATCH(TRIM(B15),""^\d{2}[/-]\d{2}[/-]\d{4}$"&"""), DATE(VALUE(RIGHT(TRIM(B15),4)),VALUE(MID(TRIM(B15),4,2)),VALUE(LEFT(TRIM(B15),2))), DATEVALUE(TRIM(B15)))), ""CHECK"")"),45471.0) -> 45471 | P15: General & Admin | Q15: G&A | R15: =IF(O15="CHECK","CHECK",TEXT(O15,"mmm")) -> Jun | S15: =IF(O15="CHECK","CHECK","Q"&INT((MONTH(O15)-1)/3)+1) -> Q2 | T15: =IFERROR(IF(G15="see notes",IF(ISNUMBER(VALUE(L15)),VALUE(L15),0),IF(G15="",0,IF(H15="GBP",VALUE(G15)*1.27,IF(AND(ISNUMBER(VALUE(G15)),F15="Revenue",VALUE(G15)<0),ABS(VALUE(G15)),IF(ISNUMBER(VALUE(G15)),VALUE(G15),0))))),0) -> 10129.21
A16: TXN-1369 | B16: 2024-09-05 | C16: Expense | D16: Engineering | E16: Eng | F16: Software License - Slack | G16: 32562.8 | H16: USD | I16: Slack | J16: Sep | K16: Q3 | N16: =IFERROR(VLOOKUP(TRIM(E16),$P$2:$Q$23,2,FALSE),"UNMAPPED - CHECK") -> Engineering | O16: =IFERROR(__xludf.DUMMYFUNCTION("IFERROR( IF(LEN(TRIM(B16))=6, DATE(2000+VALUE(RIGHT(TRIM(B16),2)),MATCH(LEFT(TRIM(B16),3),{""Jan"",""Feb"",""Mar"",""Apr"",""May"",""Jun"",""Jul"",""Aug"",""Sep"",""Oct"",""Nov"",""Dec""},0),15), IF(REGEXMATCH(TRIM(B16),""^\d{2}[/-]\d{2}[/-]\d{4}$"&"""), DATE(VALUE(RIGHT(TRIM(B16),4)),VALUE(MID(TRIM(B16),4,2)),VALUE(LEFT(TRIM(B16),2))), DATEVALUE(TRIM(B16)))), ""CHECK"")"),45540.0) -> 45540 | P16: G and A | Q16: G&A | R16: =IF(O16="CHECK","CHECK",TEXT(O16,"mmm")) -> Sep | S16: =IF(O16="CHECK","CHECK","Q"&INT((MONTH(O16)-1)/3)+1) -> Q3 | T16: =IFERROR(IF(G16="see notes",IF(ISNUMBER(VALUE(L16)),VALUE(L16),0),IF(G16="",0,IF(H16="GBP",VALUE(G16)*1.27,IF(AND(ISNUMBER(VALUE(G16)),F16="Revenue",VALUE(G16)<0),ABS(VALUE(G16)),IF(ISNUMBER(VALUE(G16)),VALUE(G16),0))))),0) -> 32562.8
A17: TXN-1272 | B17: 02-07-2024 | C17: Expense | D17: Sales | E17: Sales Dept | F17: AWS/Cloud - Delta Airlines | G17: 24078.44 | H17: USD | I17: Delta Airlines | J17: Jul | K17: Q3 | N17: =IFERROR(VLOOKUP(TRIM(E17),$P$2:$Q$23,2,FALSE),"UNMAPPED - CHECK") -> Sales | O17: =IFERROR(__xludf.DUMMYFUNCTION("IFERROR( IF(LEN(TRIM(B17))=6, DATE(2000+VALUE(RIGHT(TRIM(B17),2)),MATCH(LEFT(TRIM(B17),3),{""Jan"",""Feb"",""Mar"",""Apr"",""May"",""Jun"",""Jul"",""Aug"",""Sep"",""Oct"",""Nov"",""Dec""},0),15), IF(REGEXMATCH(TRIM(B17),""^\d{2}[/-]\d{2}[/-]\d{4}$"&"""), DATE(VALUE(RIGHT(TRIM(B17),4)),VALUE(MID(TRIM(B17),4,2)),VALUE(LEFT(TRIM(B17),2))), DATEVALUE(TRIM(B17)))), ""CHECK"")"),45475.0) -> 45475 | P17: marketing | Q17: Marketing | R17: =IF(O17="CHECK","CHECK",TEXT(O17,"mmm")) -> Jul | S17: =IF(O17="CHECK","CHECK","Q"&INT((MONTH(O17)-1)/3)+1) -> Q3 | T17: =IFERROR(IF(G17="see notes",IF(ISNUMBER(VALUE(L17)),VALUE(L17),0),IF(G17="",0,IF(H17="GBP",VALUE(G17)*1.27,IF(AND(ISNUMBER(VALUE(G17)),F17="Revenue",VALUE(G17)<0),ABS(VALUE(G17)),IF(ISNUMBER(VALUE(G17)),VALUE(G17),0))))),0) -> 24078.44
A18: TXN-1058 | B18: 02/20/2024 | C18: Expense | D18: Marketing | E18: Mktg | F18: Travel - Hilton Hotels | G18: 29097.3 | H18: USD | I18: Hilton Hotels | J18: Feb | K18: Q1 | N18: =IFERROR(VLOOKUP(TRIM(E18),$P$2:$Q$23,2,FALSE),"UNMAPPED - CHECK") -> Marketing | O18: =IFERROR(__xludf.DUMMYFUNCTION("IFERROR( IF(LEN(TRIM(B18))=6, DATE(2000+VALUE(RIGHT(TRIM(B18),2)),MATCH(LEFT(TRIM(B18),3),{""Jan"",""Feb"",""Mar"",""Apr"",""May"",""Jun"",""Jul"",""Aug"",""Sep"",""Oct"",""Nov"",""Dec""},0),15), IF(REGEXMATCH(TRIM(B18),""^\d{2}[/-]\d{2}[/-]\d{4}$"&"""), DATE(VALUE(RIGHT(TRIM(B18),4)),VALUE(MID(TRIM(B18),4,2)),VALUE(LEFT(TRIM(B18),2))), DATEVALUE(TRIM(B18)))), ""CHECK"")"),45871.0) -> 45871 | P18: Marketing | Q18: Marketing | R18: =IF(O18="CHECK","CHECK",TEXT(O18,"mmm")) -> Aug | S18: =IF(O18="CHECK","CHECK","Q"&INT((MONTH(O18)-1)/3)+1) -> Q3 | T18: =IFERROR(IF(G18="see notes",IF(ISNUMBER(VALUE(L18)),VALUE(L18),0),IF(G18="",0,IF(H18="GBP",VALUE(G18)*1.27,IF(AND(ISNUMBER(VALUE(G18)),F18="Revenue",VALUE(G18)<0),ABS(VALUE(G18)),IF(ISNUMBER(VALUE(G18)),VALUE(G18),0))))),0) -> 29097.3
A19: TXN-1001 | B19: Jan-24 | C19: Revenue | D19: Subscription | E19: Sales | F19: Subscription - Redwood Partners | G19: 559559.73 | H19: USD | I19: Sofia Andersen | J19: Jan | K19: Q1 | N19: =IFERROR(VLOOKUP(TRIM(E19),$P$2:$Q$23,2,FALSE),"UNMAPPED - CHECK") -> Sales | O19: =IFERROR(__xludf.DUMMYFUNCTION("IFERROR( IF(LEN(TRIM(B19))=6, DATE(2000+VALUE(RIGHT(TRIM(B19),2)),MATCH(LEFT(TRIM(B19),3),{""Jan"",""Feb"",""Mar"",""Apr"",""May"",""Jun"",""Jul"",""Aug"",""Sep"",""Oct"",""Nov"",""Dec""},0),15), IF(REGEXMATCH(TRIM(B19),""^\d{2}[/-]\d{2}[/-]\d{4}$"&"""), DATE(VALUE(RIGHT(TRIM(B19),4)),VALUE(MID(TRIM(B19),4,2)),VALUE(LEFT(TRIM(B19),2))), DATEVALUE(TRIM(B19)))), ""CHECK"")"),45306.0) -> 45306 | P19: Mktng | Q19: Marketing | R19: =IF(O19="CHECK","CHECK",TEXT(O19,"mmm")) -> Jan | S19: =IF(O19="CHECK","CHECK","Q"&INT((MONTH(O19)-1)/3)+1) -> Q1 | T19: =IFERROR(IF(G19="see notes",IF(ISNUMBER(VALUE(L19)),VALUE(L19),0),IF(G19="",0,IF(H19="GBP",VALUE(G19)*1.27,IF(AND(ISNUMBER(VALUE(G19)),F19="Revenue",VALUE(G19)<0),ABS(VALUE(G19)),IF(ISNUMBER(VALUE(G19)),VALUE(G19),0))))),0) -> 559559.73
A20: TXN-1256 | B20: 26-07-2024 | C20: Revenue | D20: Subscription | E20: sales | F20: Subscription - TechNova Ltd | G20: 105296.87 | H20: USD | I20: Tom Bradley | J20: Jul | K20: Q3 | N20: =IFERROR(VLOOKUP(TRIM(E20),$P$2:$Q$23,2,FALSE),"UNMAPPED - CHECK") -> Sales | O20: =IFERROR(__xludf.DUMMYFUNCTION("IFERROR( IF(LEN(TRIM(B20))=6, DATE(2000+VALUE(RIGHT(TRIM(B20),2)),MATCH(LEFT(TRIM(B20),3),{""Jan"",""Feb"",""Mar"",""Apr"",""May"",""Jun"",""Jul"",""Aug"",""Sep"",""Oct"",""Nov"",""Dec""},0),15), IF(REGEXMATCH(TRIM(B20),""^\d{2}[/-]\d{2}[/-]\d{4}$"&"""), DATE(VALUE(RIGHT(TRIM(B20),4)),VALUE(MID(TRIM(B20),4,2)),VALUE(LEFT(TRIM(B20),2))), DATEVALUE(TRIM(B20)))), ""CHECK"")"),45499.0) -> 45499 | P20: Mktg | Q20: Marketing | R20: =IF(O20="CHECK","CHECK",TEXT(O20,"mmm")) -> Jul | S20: =IF(O20="CHECK","CHECK","Q"&INT((MONTH(O20)-1)/3)+1) -> Q3 | T20: =IFERROR(IF(G20="see notes",IF(ISNUMBER(VALUE(L20)),VALUE(L20),0),IF(G20="",0,IF(H20="GBP",VALUE(G20)*1.27,IF(AND(ISNUMBER(VALUE(G20)),F20="Revenue",VALUE(G20)<0),ABS(VALUE(G20)),IF(ISNUMBER(VALUE(G20)),VALUE(G20),0))))),0) -> 105296.87
A21: TXN-1253 | B21: July 06, 2024 | C21: Revenue | D21: Subscription | E21: sales | F21: Subscription - Apex Retail | G21: 138733.49 | H21: USD | I21: Daniel Müller | J21: Jul | K21: Q3 | N21: =IFERROR(VLOOKUP(TRIM(E21),$P$2:$Q$23,2,FALSE),"UNMAPPED - CHECK") -> Sales | O21: =IFERROR(__xludf.DUMMYFUNCTION("IFERROR( IF(LEN(TRIM(B21))=6, DATE(2000+VALUE(RIGHT(TRIM(B21),2)),MATCH(LEFT(TRIM(B21),3),{""Jan"",""Feb"",""Mar"",""Apr"",""May"",""Jun"",""Jul"",""Aug"",""Sep"",""Oct"",""Nov"",""Dec""},0),15), IF(REGEXMATCH(TRIM(B21),""^\d{2}[/-]\d{2}[/-]\d{4}$"&"""), DATE(VALUE(RIGHT(TRIM(B21),4)),VALUE(MID(TRIM(B21),4,2)),VALUE(LEFT(TRIM(B21),2))), DATEVALUE(TRIM(B21)))), ""CHECK"")"),45479.0) -> 45479 | P21: sales | Q21: Sales | R21: =IF(O21="CHECK","CHECK",TEXT(O21,"mmm")) -> Jul | S21: =IF(O21="CHECK","CHECK","Q"&INT((MONTH(O21)-1)/3)+1) -> Q3 | T21: =IFERROR(IF(G21="see notes",IF(ISNUMBER(VALUE(L21)),VALUE(L21),0),IF(G21="",0,IF(H21="GBP",VALUE(G21)*1.27,IF(AND(ISNUMBER(VALUE(G21)),F21="Revenue",VALUE(G21)<0),ABS(VALUE(G21)),IF(ISNUMBER(VALUE(G21)),VALUE(G21),0))))),0) -> 138733.49
A22: TXN-1471 | B22: 23-11-2024 | C22: Expense | D22: Cloud Infrastructure | E22: cloud infra | F22: PR Agency - Zoom | G22: 33435.12 | H22: USD | I22: Zoom | J22: Nov | K22: Q4 | N22: =IFERROR(VLOOKUP(TRIM(E22),$P$2:$Q$23,2,FALSE),"UNMAPPED - CHECK") -> Cloud Infrastructure | O22: =IFERROR(__xludf.DUMMYFUNCTION("IFERROR( IF(LEN(TRIM(B22))=6, DATE(2000+VALUE(RIGHT(TRIM(B22),2)),MATCH(LEFT(TRIM(B22),3),{""Jan"",""Feb"",""Mar"",""Apr"",""May"",""Jun"",""Jul"",""Aug"",""Sep"",""Oct"",""Nov"",""Dec""},0),15), IF(REGEXMATCH(TRIM(B22),""^\d{2}[/-]\d{2}[/-]\d{4}$"&"""), DATE(VALUE(RIGHT(TRIM(B22),4)),VALUE(MID(TRIM(B22),4,2)),VALUE(LEFT(TRIM(B22),2))), DATEVALUE(TRIM(B22)))), ""CHECK"")"),45619.0) -> 45619 | P22: Sales Dept | Q22: Sales | R22: =IF(O22="CHECK","CHECK",TEXT(O22,"mmm")) -> Nov | S22: =IF(O22="CHECK","CHECK","Q"&INT((MONTH(O22)-1)/3)+1) -> Q4 | T22: =IFERROR(IF(G22="see notes",IF(ISNUMBER(VALUE(L22)),VALUE(L22),0),IF(G22="",0,IF(H22="GBP",VALUE(G22)*1.27,IF(AND(ISNUMBER(VALUE(G22)),F22="Revenue",VALUE(G22)<0),ABS(VALUE(G22)),IF(ISNUMBER(VALUE(G22)),VALUE(G22),0))))),0) -> 33435.12
A23: TXN-1385 | B23: 09/23/2024 | C23: Expense | D23: Cloud Infrastructure | E23: Cloud Infra | F23: Ad Spend - Linklaters LLP | G23: 18638.21 | H23: USD | I23: Linklaters LLP | J23: Sep | K23: Q3 | N23: =IFERROR(VLOOKUP(TRIM(E23),$P$2:$Q$23,2,FALSE),"UNMAPPED - CHECK") -> Cloud Infrastructure | O23: =IFERROR(__xludf.DUMMYFUNCTION("IFERROR( IF(LEN(TRIM(B23))=6, DATE(2000+VALUE(RIGHT(TRIM(B23),2)),MATCH(LEFT(TRIM(B23),3),{""Jan"",""Feb"",""Mar"",""Apr"",""May"",""Jun"",""Jul"",""Aug"",""Sep"",""Oct"",""Nov"",""Dec""},0),15), IF(REGEXMATCH(TRIM(B23),""^\d{2}[/-]\d{2}[/-]\d{4}$"&"""), DATE(VALUE(RIGHT(TRIM(B23),4)),VALUE(MID(TRIM(B23),4,2)),VALUE(LEFT(TRIM(B23),2))), DATEVALUE(TRIM(B23)))), ""CHECK"")"),45970.0) -> 45970 | P23: Sales | Q23: Sales | R23: =IF(O23="CHECK","CHECK",TEXT(O23,"mmm")) -> Nov | S23: =IF(O23="CHECK","CHECK","Q"&INT((MONTH(O23)-1)/3)+1) -> Q4 | T23: =IFERROR(IF(G23="see notes",IF(ISNUMBER(VALUE(L23)),VALUE(L23),0),IF(G23="",0,IF(H23="GBP",VALUE(G23)*1.27,IF(AND(ISNUMBER(VALUE(G23)),F23="Revenue",VALUE(G23)<0),ABS(VALUE(G23)),IF(ISNUMBER(VALUE(G23)),VALUE(G23),0))))),0) -> 18638.21
A24: TXN-1389 | B24: 10/10/2024 | C24: Revenue | D24: Subscription | E24: SALES | F24: Subscription - TechNova Ltd | G24: 90215.59 | H24: USD | I24: Daniel Müller | J24: Oct | K24: Q4 | N24: =IFERROR(VLOOKUP(TRIM(E24),$P$2:$Q$23,2,FALSE),"UNMAPPED - CHECK") -> Sales | O24: =IFERROR(__xludf.DUMMYFUNCTION("IFERROR( IF(LEN(TRIM(B24))=6, DATE(2000+VALUE(RIGHT(TRIM(B24),2)),MATCH(LEFT(TRIM(B24),3),{""Jan"",""Feb"",""Mar"",""Apr"",""May"",""Jun"",""Jul"",""Aug"",""Sep"",""Oct"",""Nov"",""Dec""},0),15), IF(REGEXMATCH(TRIM(B24),""^\d{2}[/-]\d{2}[/-]\d{4}$"&"""), DATE(VALUE(RIGHT(TRIM(B24),4)),VALUE(MID(TRIM(B24),4,2)),VALUE(LEFT(TRIM(B24),2))), DATEVALUE(TRIM(B24)))), ""CHECK"")"),45575.0) -> 45575 | R24: =IF(O24="CHECK","CHECK",TEXT(O24,"mmm")) -> Oct | S24: =IF(O24="CHECK","CHECK","Q"&INT((MONTH(O24)-1)/3)+1) -> Q4 | T24: =IFERROR(IF(G24="see notes",IF(ISNUMBER(VALUE(L24)),VALUE(L24),0),IF(G24="",0,IF(H24="GBP",VALUE(G24)*1.27,IF(AND(ISNUMBER(VALUE(G24)),F24="Revenue",VALUE(G24)<0),ABS(VALUE(G24)),IF(ISNUMBER(VALUE(G24)),VALUE(G24),0))))),0) -> 90215.59
A25: TXN-1402 | B25: October 13, 2024 | C25: Revenue | D25: Licensing | E25: Sales | F25: Licensing - Altura Health | G25: 7490.67 | H25: USD | I25: Tom Bradley | J25: Oct | K25: Q4 | N25: =IFERROR(VLOOKUP(TRIM(E25),$P$2:$Q$23,2,FALSE),"UNMAPPED - CHECK") -> Sales | O25: =IFERROR(__xludf.DUMMYFUNCTION("IFERROR( IF(LEN(TRIM(B25))=6, DATE(2000+VALUE(RIGHT(TRIM(B25),2)),MATCH(LEFT(TRIM(B25),3),{""Jan"",""Feb"",""Mar"",""Apr"",""May"",""Jun"",""Jul"",""Aug"",""Sep"",""Oct"",""Nov"",""Dec""},0),15), IF(REGEXMATCH(TRIM(B25),""^\d{2}[/-]\d{2}[/-]\d{4}$"&"""), DATE(VALUE(RIGHT(TRIM(B25),4)),VALUE(MID(TRIM(B25),4,2)),VALUE(LEFT(TRIM(B25),2))), DATEVALUE(TRIM(B25)))), ""CHECK"")"),45578.0) -> 45578 | R25: =IF(O25="CHECK","CHECK",TEXT(O25,"mmm")) -> Oct | S25: =IF(O25="CHECK","CHECK","Q"&INT((MONTH(O25)-1)/3)+1) -> Q4 | T25: =IFERROR(IF(G25="see notes",IF(ISNUMBER(VALUE(L25)),VALUE(L25),0),IF(G25="",0,IF(H25="GBP",VALUE(G25)*1.27,IF(AND(ISNUMBER(VALUE(G25)),F25="Revenue",VALUE(G25)<0),ABS(VALUE(G25)),IF(ISNUMBER(VALUE(G25)),VALUE(G25),0))))),0) -> 7490.67
A26: TXN-1279 | B26: July 26, 2024 | C26: Expense | D26: Engineering | E26: R&D | F26: Ad Spend - Zoom | G26: 26135.97 | H26: USD | I26: Zoom | J26: Jul | K26: Q3 | N26: =IFERROR(VLOOKUP(TRIM(E26),$P$2:$Q$23,2,FALSE),"UNMAPPED - CHECK") -> Engineering | O26: =IFERROR(__xludf.DUMMYFUNCTION("IFERROR( IF(LEN(TRIM(B26))=6, DATE(2000+VALUE(RIGHT(TRIM(B26),2)),MATCH(LEFT(TRIM(B26),3),{""Jan"",""Feb"",""Mar"",""Apr"",""May"",""Jun"",""Jul"",""Aug"",""Sep"",""Oct"",""Nov"",""Dec""},0),15), IF(REGEXMATCH(TRIM(B26),""^\d{2}[/-]\d{2}[/-]\d{4}$"&"""), DATE(VALUE(RIGHT(TRIM(B26),4)),VALUE(MID(TRIM(B26),4,2)),VALUE(LEFT(TRIM(B26),2))), DATEVALUE(TRIM(B26)))), ""CHECK"")"),45499.0) -> 45499 | R26: =IF(O26="CHECK","CHECK",TEXT(O26,"mmm")) -> Jul | S26: =IF(O26="CHECK","CHECK","Q"&INT((MONTH(O26)-1)/3)+1) -> Q3 | T26: =IFERROR(IF(G26="see notes",IF(ISNUMBER(VALUE(L26)),VALUE(L26),0),IF(G26="",0,IF(H26="GBP",VALUE(G26)*1.27,IF(AND(ISNUMBER(VALUE(G26)),F26="Revenue",VALUE(G26)<0),ABS(VALUE(G26)),IF(ISNUMBER(VALUE(G26)),VALUE(G26),0))))),0) -> 26135.97
A27: TXN-1199 | B27: May 14, 2024 | C27: Expense | D27: G&A | E27: G&A | F27: PR Agency - Delta Airlines | G27: 12105.45 | H27: USD | I27: Delta Airlines | J27: May | K27: Q2 | N27: =IFERROR(VLOOKUP(TRIM(E27),$P$2:$Q$23,2,FALSE),"UNMAPPED - CHECK") -> G&A | O27: =IFERROR(__xludf.DUMMYFUNCTION("IFERROR( IF(LEN(TRIM(B27))=6, DATE(2000+VALUE(RIGHT(TRIM(B27),2)),MATCH(LEFT(TRIM(B27),3),{""Jan"",""Feb"",""Mar"",""Apr"",""May"",""Jun"",""Jul"",""Aug"",""Sep"",""Oct"",""Nov"",""Dec""},0),15), IF(REGEXMATCH(TRIM(B27),""^\d{2}[/-]\d{2}[/-]\d{4}$"&"""), DATE(VALUE(RIGHT(TRIM(B27),4)),VALUE(MID(TRIM(B27),4,2)),VALUE(LEFT(TRIM(B27),2))), DATEVALUE(TRIM(B27)))), ""CHECK"")"),45426.0) -> 45426 | R27: =IF(O27="CHECK","CHECK",TEXT(O27,"mmm")) -> May | S27: =IF(O27="CHECK","CHECK","Q"&INT((MONTH(O27)-1)/3)+1) -> Q2 | T27: =IFERROR(IF(G27="see notes",IF(ISNUMBER(VALUE(L27)),VALUE(L27),0),IF(G27="",0,IF(H27="GBP",VALUE(G27)*1.27,IF(AND(ISNUMBER(VALUE(G27)),F27="Revenue",VALUE(G27)<0),ABS(VALUE(G27)),IF(ISNUMBER(VALUE(G27)),VALUE(G27),0))))),0) -> 12105.45
A28: TXN-1206 | B28: 2024-05-22 | C28: Expense | D28: Cloud Infrastructure | E28: Cloud Infrastructure | F28: Software License - Randstad | G28: 24138.1 | H28: USD | I28: Randstad | J28: May | K28: Q2 | N28: =IFERROR(VLOOKUP(TRIM(E28),$P$2:$Q$23,2,FALSE),"UNMAPPED - CHECK") -> Cloud Infrastructure | O28: =IFERROR(__xludf.DUMMYFUNCTION("IFERROR( IF(LEN(TRIM(B28))=6, DATE(2000+VALUE(RIGHT(TRIM(B28),2)),MATCH(LEFT(TRIM(B28),3),{""Jan"",""Feb"",""Mar"",""Apr"",""May"",""Jun"",""Jul"",""Aug"",""Sep"",""Oct"",""Nov"",""Dec""},0),15), IF(REGEXMATCH(TRIM(B28),""^\d{2}[/-]\d{2}[/-]\d{4}$"&"""), DATE(VALUE(RIGHT(TRIM(B28),4)),VALUE(MID(TRIM(B28),4,2)),VALUE(LEFT(TRIM(B28),2))), DATEVALUE(TRIM(B28)))), ""CHECK"")"),45434.0) -> 45434 | R28: =IF(O28="CHECK","CHECK",TEXT(O28,"mmm")) -> May | S28: =IF(O28="CHECK","CHECK","Q"&INT((MONTH(O28)-1)/3)+1) -> Q2 | T28: =IFERROR(IF(G28="see notes",IF(ISNUMBER(VALUE(L28)),VALUE(L28),0),IF(G28="",0,IF(H28="GBP",VALUE(G28)*1.27,IF(AND(ISNUMBER(VALUE(G28)),F28="Revenue",VALUE(G28)<0),ABS(VALUE(G28)),IF(ISNUMBER(VALUE(G28)),VALUE(G28),0))))),0) -> 24138.1
A29: TXN-1045 | B29: 2024-02-05 | C29: Revenue | D29: Professional Services | E29: SALES | F29: Professional Services - Synapse AI | G29: 20871.91 | H29: USD | I29: Kwame Asante | J29: Feb | K29: Q1 | N29: =IFERROR(VLOOKUP(TRIM(E29),$P$2:$Q$23,2,FALSE),"UNMAPPED - CHECK") -> Sales | O29: =IFERROR(__xludf.DUMMYFUNCTION("IFERROR( IF(LEN(TRIM(B29))=6, DATE(2000+VALUE(RIGHT(TRIM(B29),2)),MATCH(LEFT(TRIM(B29),3),{""Jan"",""Feb"",""Mar"",""Apr"",""May"",""Jun"",""Jul"",""Aug"",""Sep"",""Oct"",""Nov"",""Dec""},0),15), IF(REGEXMATCH(TRIM(B29),""^\d{2}[/-]\d{2}[/-]\d{4}$"&"""), DATE(VALUE(RIGHT(TRIM(B29),4)),VALUE(MID(TRIM(B29),4,2)),VALUE(LEFT(TRIM(B29),2))), DATEVALUE(TRIM(B29)))), ""CHECK"")"),45327.0) -> 45327 | R29: =IF(O29="CHECK","CHECK",TEXT(O29,"mmm")) -> Feb | S29: =IF(O29="CHECK","CHECK","Q"&INT((MONTH(O29)-1)/3)+1) -> Q1 | T29: =IFERROR(IF(G29="see notes",IF(ISNUMBER(VALUE(L29)),VALUE(L29),0),IF(G29="",0,IF(H29="GBP",VALUE(G29)*1.27,IF(AND(ISNUMBER(VALUE(G29)),F29="Revenue",VALUE(G29)<0),ABS(VALUE(G29)),IF(ISNUMBER(VALUE(G29)),VALUE(G29),0))))),0) -> 20871.91
A30: TXN-1517 | B30: 12/05/2024 | C30: Expense | D30: Cloud Infrastructure | E30: cloud infra | F30: Salary - AWS | G30: 37997.96 | H30: USD | I30: AWS | J30: Dec | K30: Q4 | N30: =IFERROR(VLOOKUP(TRIM(E30),$P$2:$Q$23,2,FALSE),"UNMAPPED - CHECK") -> Cloud Infrastructure | O30: =IFERROR(__xludf.DUMMYFUNCTION("IFERROR( IF(LEN(TRIM(B30))=6, DATE(2000+VALUE(RIGHT(TRIM(B30),2)),MATCH(LEFT(TRIM(B30),3),{""Jan"",""Feb"",""Mar"",""Apr"",""May"",""Jun"",""Jul"",""Aug"",""Sep"",""Oct"",""Nov"",""Dec""},0),15), IF(REGEXMATCH(TRIM(B30),""^\d{2}[/-]\d{2}[/-]\d{4}$"&"""), DATE(VALUE(RIGHT(TRIM(B30),4)),VALUE(MID(TRIM(B30),4,2)),VALUE(LEFT(TRIM(B30),2))), DATEVALUE(TRIM(B30)))), ""CHECK"")"),45424.0) -> 45424 | R30: =IF(O30="CHECK","CHECK",TEXT(O30,"mmm")) -> May | S30: =IF(O30="CHECK","CHECK","Q"&INT((MONTH(O30)-1)/3)+1) -> Q2 | T30: =IFERROR(IF(G30="see notes",IF(ISNUMBER(VALUE(L30)),VALUE(L30),0),IF(G30="",0,IF(H30="GBP",VALUE(G30)*1.27,IF(AND(ISNUMBER(VALUE(G30)),F30="Revenue",VALUE(G30)<0),ABS(VALUE(G30)),IF(ISNUMBER(VALUE(G30)),VALUE(G30),0))))),0) -> 37997.96
A31: TXN-1108 | B31: 2024-03-25 | C31: Expense | D31: Customer Success | E31: Customer Suc. | F31: AWS/Cloud - Randstad | G31: 22421.75 | H31: USD | I31: Randstad | J31: Mar | K31: Q1 | N31: =IFERROR(VLOOKUP(TRIM(E31),$P$2:$Q$23,2,FALSE),"UNMAPPED - CHECK") -> Customer Success | O31: =IFERROR(__xludf.DUMMYFUNCTION("IFERROR( IF(LEN(TRIM(B31))=6, DATE(2000+VALUE(RIGHT(TRIM(B31),2)),MATCH(LEFT(TRIM(B31),3),{""Jan"",""Feb"",""Mar"",""Apr"",""May"",""Jun"",""Jul"",""Aug"",""Sep"",""Oct"",""Nov"",""Dec""},0),15), IF(REGEXMATCH(TRIM(B31),""^\d{2}[/-]\d{2}[/-]\d{4}$"&"""), DATE(VALUE(RIGHT(TRIM(B31),4)),VALUE(MID(TRIM(B31),4,2)),VALUE(LEFT(TRIM(B31),2))), DATEVALUE(TRIM(B31)))), ""CHECK"")"),45376.0) -> 45376 | R31: =IF(O31="CHECK","CHECK",TEXT(O31,"mmm")) -> Mar | S31: =IF(O31="CHECK","CHECK","Q"&INT((MONTH(O31)-1)/3)+1) -> Q1 | T31: =IFERROR(IF(G31="see notes",IF(ISNUMBER(VALUE(L31)),VALUE(L31),0),IF(G31="",0,IF(H31="GBP",VALUE(G31)*1.27,IF(AND(ISNUMBER(VALUE(G31)),F31="Revenue",VALUE(G31)<0),ABS(VALUE(G31)),IF(ISNUMBER(VALUE(G31)),VALUE(G31),0))))),0) -> 22421.75
A32: TXN-1334 | B32: August 08, 2024 | C32: Expense | D32: Customer Success | E32: CS | F32: Travel - Slack | G32: 12571.55 | H32: USD | I32: Slack | J32: Aug | K32: Q3 | N32: =IFERROR(VLOOKUP(TRIM(E32),$P$2:$Q$23,2,FALSE),"UNMAPPED - CHECK") -> Customer Success | O32: =IFERROR(__xludf.DUMMYFUNCTION("IFERROR( IF(LEN(TRIM(B32))=6, DATE(2000+VALUE(RIGHT(TRIM(B32),2)),MATCH(LEFT(TRIM(B32),3),{""Jan"",""Feb"",""Mar"",""Apr"",""May"",""Jun"",""Jul"",""Aug"",""Sep"",""Oct"",""Nov"",""Dec""},0),15), IF(REGEXMATCH(TRIM(B32),""^\d{2}[/-]\d{2}[/-]\d{4}$"&"""), DATE(VALUE(RIGHT(TRIM(B32),4)),VALUE(MID(TRIM(B32),4,2)),VALUE(LEFT(TRIM(B32),2))), DATEVALUE(TRIM(B32)))), ""CHECK"")"),45512.0) -> 45512 | R32: =IF(O32="CHECK","CHECK",TEXT(O32,"mmm")) -> Aug | S32: =IF(O32="CHECK","CHECK","Q"&INT((MONTH(O32)-1)/3)+1) -> Q3 | T32: =IFERROR(IF(G32="see notes",IF(ISNUMBER(VALUE(L32)),VALUE(L32),0),IF(G32="",0,IF(H32="GBP",VALUE(G32)*1.27,IF(AND(ISNUMBER(VALUE(G32)),F32="Revenue",VALUE(G32)<0),ABS(VALUE(G32)),IF(ISNUMBER(VALUE(G32)),VALUE(G32),0))))),0) -> 12571.55
A33: TXN-1032 | B33: 22/01/2024 | C33: Expense | D33: G&A | E33: General & Admin | F33: Ad Spend - WeWork | G33: 12219.14 | H33: USD | I33: WeWork | J33: Jan | K33: Q1 | N33: =IFERROR(VLOOKUP(TRIM(E33),$P$2:$Q$23,2,FALSE),"UNMAPPED - CHECK") -> G&A | O33: =IFERROR(__xludf.DUMMYFUNCTION("IFERROR( IF(LEN(TRIM(B33))=6, DATE(2000+VALUE(RIGHT(TRIM(B33),2)),MATCH(LEFT(TRIM(B33),3),{""Jan"",""Feb"",""Mar"",""Apr"",""May"",""Jun"",""Jul"",""Aug"",""Sep"",""Oct"",""Nov"",""Dec""},0),15), IF(REGEXMATCH(TRIM(B33),""^\d{2}[/-]\d{2}[/-]\d{4}$"&"""), DATE(VALUE(RIGHT(TRIM(B33),4)),VALUE(MID(TRIM(B33),4,2)),VALUE(LEFT(TRIM(B33),2))), DATEVALUE(TRIM(B33)))), ""CHECK"")"),45313.0) -> 45313 | R33: =IF(O33="CHECK","CHECK",TEXT(O33,"mmm")) -> Jan | S33: =IF(O33="CHECK","CHECK","Q"&INT((MONTH(O33)-1)/3)+1) -> Q1 | T33: =IFERROR(IF(G33="see notes",IF(ISNUMBER(VALUE(L33)),VALUE(L33),0),IF(G33="",0,IF(H33="GBP",VALUE(G33)*1.27,IF(AND(ISNUMBER(VALUE(G33)),F33="Revenue",VALUE(G33)<0),ABS(VALUE(G33)),IF(ISNUMBER(VALUE(G33)),VALUE(G33),0))))),0) -> 12219.14
A34: TXN-1232 | B34: 06/06/2024 | C34: Expense | D34: Engineering | E34: Eng | F34: Software License - Linklaters LLP | G34: 30079.33 | H34: USD | I34: Linklaters LLP | J34: Jun | K34: Q2 | N34: =IFERROR(VLOOKUP(TRIM(E34),$P$2:$Q$23,2,FALSE),"UNMAPPED - CHECK") -> Engineering | O34: =IFERROR(__xludf.DUMMYFUNCTION("IFERROR( IF(LEN(TRIM(B34))=6, DATE(2000+VALUE(RIGHT(TRIM(B34),2)),MATCH(LEFT(TRIM(B34),3),{""Jan"",""Feb"",""Mar"",""Apr"",""May"",""Jun"",""Jul"",""Aug"",""Sep"",""Oct"",""Nov"",""Dec""},0),15), IF(REGEXMATCH(TRIM(B34),""^\d{2}[/-]\d{2}[/-]\d{4}$"&"""), DATE(VALUE(RIGHT(TRIM(B34),4)),VALUE(MID(TRIM(B34),4,2)),VALUE(LEFT(TRIM(B34),2))), DATEVALUE(TRIM(B34)))), ""CHECK"")"),45449.0) -> 45449 | R34: =IF(O34="CHECK","CHECK",TEXT(O34,"mmm")) -> Jun | S34: =IF(O34="CHECK","CHECK","Q"&INT((MONTH(O34)-1)/3)+1) -> Q2 | T34: =IFERROR(IF(G34="see notes",IF(ISNUMBER(VALUE(L34)),VALUE(L34),0),IF(G34="",0,IF(H34="GBP",VALUE(G34)*1.27,IF(AND(ISNUMBER(VALUE(G34)),F34="Revenue",VALUE(G34)<0),ABS(VALUE(G34)),IF(ISNUMBER(VALUE(G34)),VALUE(G34),0))))),0) -> 30079.33
A35: TXN-1159 | B35: 28-04-2024 | C35: Expense | D35: Cloud Infrastructure | E35: CLOUD | F35: Ad Spend - Delta Airlines | G35: 13746.82 | H35: USD | I35: Delta Airlines | J35: Apr | K35: Q2 | N35: =IFERROR(VLOOKUP(TRIM(E35),$P$2:$Q$23,2,FALSE),"UNMAPPED - CHECK") -> Cloud Infrastructure | O35: =IFERROR(__xludf.DUMMYFUNCTION("IFERROR( IF(LEN(TRIM(B35))=6, DATE(2000+VALUE(RIGHT(TRIM(B35),2)),MATCH(LEFT(TRIM(B35),3),{""Jan"",""Feb"",""Mar"",""Apr"",""May"",""Jun"",""Jul"",""Aug"",""Sep"",""Oct"",""Nov"",""Dec""},0),15), IF(REGEXMATCH(TRIM(B35),""^\d{2}[/-]\d{2}[/-]\d{4}$"&"""), DATE(VALUE(RIGHT(TRIM(B35),4)),VALUE(MID(TRIM(B35),4,2)),VALUE(LEFT(TRIM(B35),2))), DATEVALUE(TRIM(B35)))), ""CHECK"")"),45410.0) -> 45410 | R35: =IF(O35="CHECK","CHECK",TEXT(O35,"mmm")) -> Apr | S35: =IF(O35="CHECK","CHECK","Q"&INT((MONTH(O35)-1)/3)+1) -> Q2 | T35: =IFERROR(IF(G35="see notes",IF(ISNUMBER(VALUE(L35)),VALUE(L35),0),IF(G35="",0,IF(H35="GBP",VALUE(G35)*1.27,IF(AND(ISNUMBER(VALUE(G35)),F35="Revenue",VALUE(G35)<0),ABS(VALUE(G35)),IF(ISNUMBER(VALUE(G35)),VALUE(G35),0))))),0) -> 13746.82
A36: TXN-1118 | B36: 20-03-2024 | C36: Expense | D36: Cloud Infrastructure | E36: Cloud Infrastructure | F36: Travel - Slack | G36: 18874.72 | H36: USD | I36: Slack | J36: Mar | K36: Q1 | N36: =IFERROR(VLOOKUP(TRIM(E36),$P$2:$Q$23,2,FALSE),"UNMAPPED - CHECK") -> Cloud Infrastructure | O36: =IFERROR(__xludf.DUMMYFUNCTION("IFERROR( IF(LEN(TRIM(B36))=6, DATE(2000+VALUE(RIGHT(TRIM(B36),2)),MATCH(LEFT(TRIM(B36),3),{""Jan"",""Feb"",""Mar"",""Apr"",""May"",""Jun"",""Jul"",""Aug"",""Sep"",""Oct"",""Nov"",""Dec""},0),15), IF(REGEXMATCH(TRIM(B36),""^\d{2}[/-]\d{2}[/-]\d{4}$"&"""), DATE(VALUE(RIGHT(TRIM(B36),4)),VALUE(MID(TRIM(B36),4,2)),VALUE(LEFT(TRIM(B36),2))), DATEVALUE(TRIM(B36)))), ""CHECK"")"),45371.0) -> 45371 | R36: =IF(O36="CHECK","CHECK",TEXT(O36,"mmm")) -> Mar | S36: =IF(O36="CHECK","CHECK","Q"&INT((MONTH(O36)-1)/3)+1) -> Q1 | T36: =IFERROR(IF(G36="see notes",IF(ISNUMBER(VALUE(L36)),VALUE(L36),0),IF(G36="",0,IF(H36="GBP",VALUE(G36)*1.27,IF(AND(ISNUMBER(VALUE(G36)),F36="Revenue",VALUE(G36)<0),ABS(VALUE(G36)),IF(ISNUMBER(VALUE(G36)),VALUE(G36),0))))),0) -> 18874.72
A37: TXN-1211 | B37: 2024-06-28 | C37: Revenue | D37: Subscription | E37: SALES | F37: Subscription - Orion Media | G37: 144260.58 | H37: USD | I37: Priya Nair | J37: Jun | K37: Q2 | N37: =IFERROR(VLOOKUP(TRIM(E37),$P$2:$Q$23,2,FALSE),"UNMAPPED - CHECK") -> Sales | O37: =IFERROR(__xludf.DUMMYFUNCTION("IFERROR( IF(LEN(TRIM(B37))=6, DATE(2000+VALUE(RIGHT(TRIM(B37),2)),MATCH(LEFT(TRIM(B37),3),{""Jan"",""Feb"",""Mar"",""Apr"",""May"",""Jun"",""Jul"",""Aug"",""Sep"",""Oct"",""Nov"",""Dec""},0),15), IF(REGEXMATCH(TRIM(B37),""^\d{2}[/-]\d{2}[/-]\d{4}$"&"""), DATE(VALUE(RIGHT(TRIM(B37),4)),VALUE(MID(TRIM(B37),4,2)),VALUE(LEFT(TRIM(B37),2))), DATEVALUE(TRIM(B37)))), ""CHECK"")"),45471.0) -> 45471 | R37: =IF(O37="CHECK","CHECK",TEXT(O37,"mmm")) -> Jun | S37: =IF(O37="CHECK","CHECK","Q"&INT((MONTH(O37)-1)/3)+1) -> Q2 | T37: =IFERROR(IF(G37="see notes",IF(ISNUMBER(VALUE(L37)),VALUE(L37),0),IF(G37="",0,IF(H37="GBP",VALUE(G37)*1.27,IF(AND(ISNUMBER(VALUE(G37)),F37="Revenue",VALUE(G37)<0),ABS(VALUE(G37)),IF(ISNUMBER(VALUE(G37)),VALUE(G37),0))))),0) -> 144260.58
A38: TXN-1352 | B38: September 19, 2024 | C38: Revenue | D38: Professional Services | E38: SALES | F38: Professional Services - Vertex Analytics | G38: 24777.81 | H38: USD | I38: James Okafor | J38: Sep | K38: Q3 | N38: =IFERROR(VLOOKUP(TRIM(E38),$P$2:$Q$23,2,FALSE),"UNMAPPED - CHECK") -> Sales | O38: =IFERROR(__xludf.DUMMYFUNCTION("IFERROR( IF(LEN(TRIM(B38))=6, DATE(2000+VALUE(RIGHT(TRIM(B38),2)),MATCH(LEFT(TRIM(B38),3),{""Jan"",""Feb"",""Mar"",""Apr"",""May"",""Jun"",""Jul"",""Aug"",""Sep"",""Oct"",""Nov"",""Dec""},0),15), IF(REGEXMATCH(TRIM(B38),""^\d{2}[/-]\d{2}[/-]\d{4}$"&"""), DATE(VALUE(RIGHT(TRIM(B38),4)),VALUE(MID(TRIM(B38),4,2)),VALUE(LEFT(TRIM(B38),2))), DATEVALUE(TRIM(B38)))), ""CHECK"")"),45554.0) -> 45554 | R38: =IF(O38="CHECK","CHECK",TEXT(O38,"mmm")) -> Sep | S38: =IF(O38="CHECK","CHECK","Q"&INT((MONTH(O38)-1)/3)+1) -> Q3 | T38: =IFERROR(IF(G38="see notes",IF(ISNUMBER(VALUE(L38)),VALUE(L38),0),IF(G38="",0,IF(H38="GBP",VALUE(G38)*1.27,IF(AND(ISNUMBER(VALUE(G38)),F38="Revenue",VALUE(G38)<0),ABS(VALUE(G38)),IF(ISNUMBER(VALUE(G38)),VALUE(G38),0))))),0) -> 24777.81
A39: TXN-1374 | B39: 19-09-2024 | C39: Expense | D39: Customer Success | E39: CS | F39: Travel - Linklaters LLP | G39: 27990.06 | H39: USD | I39: Linklaters LLP | J39: Sep | K39: Q3 | N39: =IFERROR(VLOOKUP(TRIM(E39),$P$2:$Q$23,2,FALSE),"UNMAPPED - CHECK") -> Customer Success | O39: =IFERROR(__xludf.DUMMYFUNCTION("IFERROR( IF(LEN(TRIM(B39))=6, DATE(2000+VALUE(RIGHT(TRIM(B39),2)),MATCH(LEFT(TRIM(B39),3),{""Jan"",""Feb"",""Mar"",""Apr"",""May"",""Jun"",""Jul"",""Aug"",""Sep"",""Oct"",""Nov"",""Dec""},0),15), IF(REGEXMATCH(TRIM(B39),""^\d{2}[/-]\d{2}[/-]\d{4}$"&"""), DATE(VALUE(RIGHT(TRIM(B39),4)),VALUE(MID(TRIM(B39),4,2)),VALUE(LEFT(TRIM(B39),2))), DATEVALUE(TRIM(B39)))), ""CHECK"")"),45554.0) -> 45554 | R39: =IF(O39="CHECK","CHECK",TEXT(O39,"mmm")) -> Sep | S39: =IF(O39="CHECK","CHECK","Q"&INT((MONTH(O39)-1)/3)+1) -> Q3 | T39: =IFERROR(IF(G39="see notes",IF(ISNUMBER(VALUE(L39)),VALUE(L39),0),IF(G39="",0,IF(H39="GBP",VALUE(G39)*1.27,IF(AND(ISNUMBER(VALUE(G39)),F39="Revenue",VALUE(G39)<0),ABS(VALUE(G39)),IF(ISNUMBER(VALUE(G39)),VALUE(G39),0))))),0) -> 27990.06
A40: TXN-1229 | B40: 06/03/2024 | C40: Expense | D40: Marketing | E40: MARKETING | F40: AWS/Cloud - WeWork | G40: 58324.51 | H40: USD | I40: WeWork | J40: Jun | K40: Q2 | N40: =IFERROR(VLOOKUP(TRIM(E40),$P$2:$Q$23,2,FALSE),"UNMAPPED - CHECK") -> Marketing | O40: =IFERROR(__xludf.DUMMYFUNCTION("IFERROR( IF(LEN(TRIM(B40))=6, DATE(2000+VALUE(RIGHT(TRIM(B40),2)),MATCH(LEFT(TRIM(B40),3),{""Jan"",""Feb"",""Mar"",""Apr"",""May"",""Jun"",""Jul"",""Aug"",""Sep"",""Oct"",""Nov"",""Dec""},0),15), IF(REGEXMATCH(TRIM(B40),""^\d{2}[/-]\d{2}[/-]\d{4}$"&"""), DATE(VALUE(RIGHT(TRIM(B40),4)),VALUE(MID(TRIM(B40),4,2)),VALUE(LEFT(TRIM(B40),2))), DATEVALUE(TRIM(B40)))), ""CHECK"")"),45357.0) -> 45357 | R40: =IF(O40="CHECK","CHECK",TEXT(O40,"mmm")) -> Mar | S40: =IF(O40="CHECK","CHECK","Q"&INT((MONTH(O40)-1)/3)+1) -> Q1 | T40: =IFERROR(IF(G40="see notes",IF(ISNUMBER(VALUE(L40)),VALUE(L40),0),IF(G40="",0,IF(H40="GBP",VALUE(G40)*1.27,IF(AND(ISNUMBER(VALUE(G40)),F40="Revenue",VALUE(G40)<0),ABS(VALUE(G40)),IF(ISNUMBER(VALUE(G40)),VALUE(G40),0))))),0) -> 58324.51
...

Sheet Pivot Table 2

Sheet Analysis
A1: NEXORA SOFTWARE — FY2024 FINANCIAL ANALYSIS
A2: Analyst: Temmygabriel | Source: Cleaned Data sheet | All amounts in USD
A4: REVENUE SUMMARY
A5: Category | B5: Total Actual ($) | C5: Notes
A6: Subscription | B6: =SUMIFS(Cleaned_sheet!$T:$T,Cleaned_sheet!$C:$C,"Revenue",Cleaned_sheet!$D:$D,"Subscription") -> 11155691 | C6: Core ARR — 83% of total revenue
A7: Professional Services | B7: =SUMIFS(Cleaned_sheet!$T:$T,Cleaned_sheet!$C:$C,"Revenue",Cleaned_sheet!$D:$D,"Professional Services") -> 1569600 | C7: Outperformed budget every month — investigate for FY2025
A8: Licensing | B8: =SUMIFS(Cleaned_sheet!$T:$T,Cleaned_sheet!$C:$C,"Revenue",Cleaned_sheet!$D:$D,"Licensing") -> 647919.31 | C8: One-off deals — lumpy by nature
A9: Contra-Revenue | B9: =SUMIFS(Cleaned_sheet!$T:$T,Cleaned_sheet!$C:$C,"Contra-Revenue") -> -13442.93 | C9: Client refunds — minimal impact
A10: TOTAL REVENUE | B10: =SUMIFS(Cleaned_sheet!$T:$T,Cleaned_sheet!$C:$C,"Revenue")+SUMIFS(Cleaned_sheet!$T:$T,Cleaned_sheet!$C:$C,"Contra-Revenue") -> 13359768 | C10: Full year top line
A12: EXPENSE SUMMARY
A13: Department | B13: Total Actual ($) | C13: Notes
A14: Marketing | B14: =SUMIFS(Cleaned_sheet!$T:$T,Cleaned_sheet!$C:$C,"Expense",Cleaned_sheet!$N:$N,"Marketing") -> 2298600 | C14: Largest cost centre — 28% of total opex. Q3 spend spike warrants investigation
A15: Engineering | B15: =SUMIFS(Cleaned_sheet!$T:$T,Cleaned_sheet!$C:$C,"Expense",Cleaned_sheet!$N:$N,"Engineering") -> 1562600 | C15: Product development — expected for a SaaS business
A16: Cloud Infrastructure | B16: =SUMIFS(Cleaned_sheet!$T:$T,Cleaned_sheet!$C:$C,"Expense",Cleaned_sheet!$N:$N,"Cloud infrastructure") -> 1417863.7 | C16: Costs crept up every month in H2 — trend more concerning than annual total
A17: Sales | B17: =SUMIFS(Cleaned_sheet!$T:$T,Cleaned_sheet!$C:$C,"Expense",Cleaned_sheet!$N:$N,"Sales") -> 1168718.4 | C17: Sales team overhead — reasonable relative to revenue generated
A18: Customer Success | B18: =SUMIFS(Cleaned_sheet!$T:$T,Cleaned_sheet!$C:$C,"Expense",Cleaned_sheet!$N:$N,"Customer Success") -> 907500 | C18: Lean team supporting $13M revenue — efficient
A19: G&A | B19: =SUMIFS(Cleaned_sheet!$T:$T,Cleaned_sheet!$C:$C,"Expense",Cleaned_sheet!$N:$N,"G&A") -> 729721.97 | C19: Lowest cost centre — well controlled
A20: TOTAL OPEX | B20: =SUM(B14:B19) -> 8085004 | C20: Full year operating expenses
A22: NET POSITION | B22: Total Actual ($)
A23: Total Revenue | B23: =B10 -> 13359768
A24: Total OPEX | B24: =B20 -> 8085004
A25: NET INCOME | B25: =B23-B24 -> 5274763.6
A27: QUARTERLY BREAKDOWN — REVENUE vs EXPENSE
A28: Quarter | B28: Total Revenue ($) | C28: Total Expense ($) | D28: Net ($) | E28: Notes
A29: Q1 | B29: =SUMIFS(Cleaned_sheet!$T:$T,Cleaned_sheet!$C:$C,"Revenue",Cleaned_sheet!$S:$S,"Q1") -> 2860278.1 | C29: =SUMIFS(Cleaned_sheet!$T:$T,Cleaned_sheet!$C:$C,"Expense",Cleaned_sheet!$S:$S,"Q1") -> 1947438.1 | D29: =B29-C29 -> 912840 | E29: Solid start — revenue and expenses both stable
A30: Q2 | B30: =SUMIFS(Cleaned_sheet!$T:$T,Cleaned_sheet!$C:$C,"Revenue",Cleaned_sheet!$S:$S,"Q2") -> 3107888.8 | C30: =SUMIFS(Cleaned_sheet!$T:$T,Cleaned_sheet!$C:$C,"Expense",Cleaned_sheet!$S:$S,"Q2") -> 2320000.1 | D30: =B30-C30 -> 787888.76 | E30: Net dipped — expenses grew faster than revenue. Q2 pressure point.
A31: Q3 | B31: =SUMIFS(Cleaned_sheet!$T:$T,Cleaned_sheet!$C:$C,"Revenue",Cleaned_sheet!$S:$S,"Q3") -> 3290359 | C31: =SUMIFS(Cleaned_sheet!$T:$T,Cleaned_sheet!$C:$C,"Expense",Cleaned_sheet!$S:$S,"Q3") -> 2093850.4 | D31: =B31-C31 -> 1196508.6 | E31: Net recovered but Marketing spend peaked this quarter — efficiency question
A32: Q4 | B32: =SUMIFS(Cleaned_sheet!$T:$T,Cleaned_sheet!$C:$C,"Revenue",Cleaned_sheet!$S:$S,"Q4") -> 4114684.7 | C32: =SUMIFS(Cleaned_sheet!$T:$T,Cleaned_sheet!$C:$C,"Expense",Cleaned_sheet!$S:$S,"Q4") -> 1723715.5 | D32: =B32-C32 -> 2390969.2 | E32: Strongest quarter — Q4 recovery real but came late in the year
A33: FULL YEAR | B33: =SUM(B29:B32) -> 13373211 | C33: =SUM(C29:C32) -> 8085004 | D33: =B33-C33 -> 5288206.5 | E33: Full year net position
A35: MARKETING EFFICIENCY ANALYSIS — Q3 DEEP DIVE
A36: Quarter | B36: Marketing Spend ($) | C36: Notes
A37: Q1 | B37: =SUMIFS(Cleaned_sheet!$T:$T,Cleaned_sheet!$C:$C,"Expense",Cleaned_sheet!$N:$N,"Marketing",Cleaned_sheet!$S:$S,"Q1") -> 661013.88 | C37: Highest spend quarter — heavy H1 investment
A38: Q2 | B38: =SUMIFS(Cleaned_sheet!$T:$T,Cleaned_sheet!$C:$C,"Expense",Cleaned_sheet!$N:$N,"Marketing",Cleaned_sheet!$S:$S,"Q2") -> 627488.46 | C38: Spend eased slightly
A39: Q3 | B39: =SUMIFS(Cleaned_sheet!$T:$T,Cleaned_sheet!$C:$C,"Expense",Cleaned_sheet!$N:$N,"Marketing",Cleaned_sheet!$S:$S,"Q3") -> 630079.71 | C39: Marginal increase over Q2 — spend remained elevated
A40: Q4 | B40: =SUMIFS(Cleaned_sheet!$T:$T,Cleaned_sheet!$C:$C,"Expense",Cleaned_sheet!$N:$N,"Marketing",Cleaned_sheet!$S:$S,"Q4") -> 380017.95 | C40: Sharp pullback — but Q4 revenue was strongest. Efficiency question
A42: H1 Marketing Spend | B42: =B37+B38 -> 1288502.3
A43: H2 Marketing Spend | B43: =B39+B40 -> 1010097.7
A44: H1 vs H2 Difference | B44: =B42-B43 -> 278404.68

Sheet Power_BI_Export
A1: Transaction_ID | B1: Date_Raw | C1: Type | D1: Category | E1: Department_Raw | F1: Dept_Clean | G1: Date_Clean | H1: Month_Clean | I1: Quarter_Clean | J1: Amount_USD
A2: {={Cleaned_sheet!A2:A521,Cleaned_sheet!B2:B521,Cleaned_sheet!C2:C521,Cleaned_sheet!D2:D521,Cleaned_sheet!E2:E521,Cleaned_sheet!N2:N521,Cleaned_sheet!O2:O521,Cleaned_sheet!R2:R521,Cleaned_sheet!S2:S521,Cleaned_sheet!T2:T521}} -> TXN-1003 | B2: 09-01-2024 | C2: Revenue | D2: Subscription | E2: Sales Dept | F2: Sales | G2: 45300 | H2: Jan | I2: Q1 | J2: 68037.03
A3: TXN-1519 | B3: 2024-12-25 | C3: Expense | D3: Cloud Infrastructure | E3: cloud infra | F3: Cloud Infrastructure | G3: 45651 | H3: Dec | I3: Q4 | J3: 39375.28
A4: TXN-1083 | B4: 03/20/2024 | C4: Revenue | D4: Subscription | E4: Sales Dept | F4: Sales | G4: 45872 | H4: Aug | I4: Q3 | J4: 251866.75
A5: TXN-1428 | B5: October 22, 2024 | C5: Expense | D5: Cloud Infrastructure | E5: CLOUD | F5: Cloud Infrastructure | G5: 45587 | H5: Oct | I5: Q4 | J5: 22219.83
A6: TXN-1276 | B6: 03-07-2024 | C6: Expense | D6: Marketing | E6: marketing | F6: Marketing | G6: 45476 | H6: Jul | I6: Q3 | J6: 54150.77
A7: TXN-1129 | B7: April 14, 2024 | C7: Revenue | D7: Licensing | E7: sales | F7: Sales | G7: 45396 | H7: Apr | I7: Q2 | J7: 6708.47
A8: TXN-1348 | B8: 2024-09-15 | C8: Revenue | D8: Subscription | E8: sales | F8: Sales | G8: 45550 | H8: Sep | I8: Q3 | J8: 149903.37
A9: TXN-1295 | B9: 07/21/2024 | C9: Expense | D9: Cloud Infrastructure | E9: Cloud | F9: Cloud Infrastructure | G9: 45907 | H9: Sep | I9: Q3 | J9: 12717.64
A10: TXN-1170 | B10: 10-05-2024 | C10: Revenue | D10: Professional Services | E10: Sales Dept | F10: Sales | G10: 45422 | H10: May | I10: Q2 | J10: 21411.91
A11: TXN-1379 | B11: Sep-24 | C11: Expense | D11: G&A | E11: G and A | F11: G&A | G11: 45550 | H11: Sep | I11: Q3 | J11: 9918.62
A12: TXN-1131 | B12: 06/04/2024 | C12: Revenue | D12: Licensing | E12: SALES | F12: Sales | G12: 45388 | H12: Apr | I12: Q2 | J12: 6750.78
A13: TXN-1117 | B13: Mar-24 | C13: Expense | D13: Cloud Infrastructure | E13: Cloud | F13: Cloud Infrastructure | G13: 45366 | H13: Mar | I13: Q1 | J13: 16812.38
A14: TXN-1328 | B14: Aug-24 | C14: Expense | D14: Engineering | E14: Eng | F14: Engineering | G14: 45519 | H14: Aug | I14: Q3 | J14: 21612.23
... A521: TXN-1422 | B521: November 05, 2024 | C521: Expense | D521: G&A | E521: General & Admin | F521: G&A | G521: 45601 | H521: Nov | I521: Q4 | J521: 27339.38
